Workbook

Sheet F-SENCILLOS
A1: UNIDADES DE FULL HACIENDO VIAJES DE SENCILLO 12-02-2026 AL DIA 26-02-2026
A2: COMENTARIO | B2: TipoRemolque | C2: NumFase | D2: Status | E2: Viajes.CrUsuario | F2: ID | G2: FechaProgCarga | H2: FechaRealCarga | I2: FechaInicioReal | J2: FechaRealDescarga | K2: ID_Tractor | L2: ID_Operador | M2: Operadores.Descripcion | N2: Clientes.Descripcion | O2: ID_Ruta | P2: Origen | Q2: Destino | R2: Numremision | S2: NumCarga | T2: Kilometros | U2: ImporteFlete | V2: Observaciones | W2: ImporteManiobras | X2: ID_Factura | Y2: ImporteFacturado | Z2: ImporteOtros1 | AA2: ImporteOtros2 | AB2: ImporteAutopistas | AC2: ImporteSeguro | AD2: TotLitros | AE2: ID_Permisionario | AF2: ImporteTotal | AG2: DocumentacionViajeRecibida | AH2: DocumentacionCorrecta | AI2: FechaRecepcionDoctos | AJ2: UsuarioRecibioDoctos | AK2: UsuarioEntregoDoctos | AL2: FechaSeFacturo | AM2: facturas.CrUsuario | AN2: DescripcionRemolque1 | AO2: DescripcionRemolque2
A3: UNIDAD DE FULL PUEBLA | B3: S | C3: 4 | D3: C | E3: OSCARA | F3: 16759 | G3: 46065 | H3: 46065 | I3: 46065 | J3: 46065 | K3: TRA-341 | L3: 00274 | M3: TEHUITZIL MARTINEZ, JOSE REFUGIO | N3: WALMART PUEBLA | O3: HUBP-ALEN | P3: PUEBLA, PUEBLA | Q3: PUEBLA, PUEBLA | R3: 589849-V | S3: 23276864 | T3: 11.4 | U3: 0 | V3: RECOLECCION | W3: 0 | X3: FWP-0240649 | Y3: 281.21 | Z3: 0.13 | AA3: 106.08 | AB3: 175 | AC3: 0 | AD3: 82 | AG3: 0 | AH3: 0 | AL3: 46066.602 | AM3: JUANMGC | AN3: 37UG8M
A4: UNIDAD DE FULL PUEBLA | B4: S | C4: 4 | D4: C | E4: OSCARA | F4: 16760 | G4: 46065 | H4: 46065 | I4: 46065 | J4: 46065 | K4: TRA-341 | L4: 00274 | M4: TEHUITZIL MARTINEZ, JOSE REFUGIO | N4: WALMART PUEBLA | O4: ALEN-HUBP | P4: PUEBLA, PUEBLA | Q4: PUEBLA, PUEBLA | R4: 589849-C | S4: 23276871 | T4: 13.1 | U4: 0 | V4: 260302128 | W4: 0 | X4: FWP-0240710 | Y4: 295.95 | Z4: 0.11 | AA4: 92.39 | AB4: 203.45 | AC4: 0 | AD4: 11 | AG4: 0 | AH4: 0 | AL4: 46066.639 | AM4: JUANMGC | AN4: 430YH5
A5: UNIDAD DE FULL PUEBLA | B5: S | C5: 4 | D5: C | E5: OSCARA | F5: 16762 | G5: 46065 | H5: 46065 | I5: 46065 | J5: 46065 | K5: TRA-341 | L5: 00274 | M5: TEHUITZIL MARTINEZ, JOSE REFUGIO | N5: WALMART PUEBLA | O5: HUBP-ALEN | P5: PUEBLA, PUEBLA | Q5: PUEBLA, PUEBLA | R5: 589850-V | S5: 23276881 | T5: 11.4 | U5: 0 | V5: RECOLECCION | W5: 0 | X5: FWP-0240650 | Y5: 281.21 | Z5: 0.13 | AA5: 106.08 | AB5: 175 | AC5: 0 | AD5: 14 | AG5: 0 | AH5: 0 | AL5: 46066.602 | AM5: JUANMGC | AN5: 720YG5
A6: UNIDAD DE FULL PUEBLA | B6: S | C6: 4 | D6: C | E6: OSCARA | F6: 16766 | G6: 46065 | H6: 46065 | I6: 46065 | J6: 46065 | K6: TRA-341 | L6: 00274 | M6: TEHUITZIL MARTINEZ, JOSE REFUGIO | N6: WALMART PUEBLA | O6: ALEN-HUBP | P6: PUEBLA, PUEBLA | Q6: PUEBLA, PUEBLA | R6: 589850-C | S6: 23276885 | T6: 13.1 | U6: 0 | V6: 260302209 | W6: 0 | X6: FWP-0240711 | Y6: 295.95 | Z6: 0.11 | AA6: 92.39 | AB6: 203.45 | AC6: 0 | AG6: 0 | AH6: 0 | AL6: 46066.64 | AM6: JUANMGC | AN6: 09UG8M
A7: UNIDAD DE FULL PUEBLA | B7: S | C7: 4 | D7: C | E7: ALMAVIVAS | F7: 17147 | G7: 46066 | H7: 46066 | I7: 46067 | J7: 46067 | K7: TRA-214 | L7: 00037 | M7: CAMPOS GARCIA, BOMFILIO | N7: WALMART PUEBLA | O7: HUBP-6312 | P7: PUEBLA, PUEBLA | Q7: PUEBLA, PUEBLA | R7: 604324-C | S7: 23279475 | T7: 14.5 | U7: 0 | V7: 1306840/1306839 / DOC EN COPIA | W7: 0 | X7: FWP-0240808 | Y7: 431.1 | Z7: 131.08 | AA7: 125.02 | AB7: 175 | AC7: 0 | AG7: 1 | AH7: 1 | AI7: 46072.501 | AJ7: ALEJANDRO MENDEZ | AK7: BONIFILIO CAMPOS GARCIA | AL7: 46067.954 | AM7: ALBAAN | AN7: 883YG5
A8: UNIDAD DE FULL PUEBLA | B8: S | C8: 4 | D8: C | E8: ALMAVIVAS | F8: 17148 | G8: 46067 | H8: 46067 | I8: 46067 | J8: 46067 | K8: TRA-214 | L8: 00037 | M8: CAMPOS GARCIA, BOMFILIO | N8: WALMART PUEBLA | O8: 6312-HUBP | P8: PUEBLA, PUEBLA | Q8: PUEBLA, PUEBLA | R8: 604324-V | S8: 23288821 | T8: 12.8 | U8: 0 | V8: 604324-V / DOC EN COPIA | W8: 0 | X8: FWP-0240998 | Y8: 429.54 | Z8: 115.71 | AA8: 110.38 | AB8: 203.45 | AC8: 0 | AG8: 1 | AH8: 1 | AI8: 46072.501 | AJ8: ALEJANDRO MENDEZ | AK8: BONIFILIO CAMPOS GARCIA | AL8: 46069.771 | AM8: CARLOSPC | AN8: 883YG5
A9: UNIDAD DE FULL PUEBLA | B9: S | C9: 4 | D9: C | E9: MONICAH | F9: 17184 | G9: 46066 | H9: 46066 | I9: 46067 | J9: 46067 | K9: TRA-345 | L9: 00702 | M9: TLAPANCO MORALES, JUAN | N9: WALMART PUEBLA | O9: HUBP-6312 | P9: PUEBLA, PUEBLA | Q9: PUEBLA, PUEBLA | R9: 604379-C | S9: 23289789 | T9: 14.5 | U9: 0 | V9: 1306909/1306910 / DOC EN COPIA | W9: 0 | X9: FWP-0241054 | Y9: 431.12 | Z9: 131.08 | AA9: 125.04 | AB9: 175 | AC9: 0 | AG9: 1 | AH9: 1 | AI9: 46072.508 | AJ9: ALEJANDRO MENDEZ | AK9: JUAN TLAPANCO MORALES | AL9: 46069.9 | AM9: JUANMGC | AN9: 335YG4
A10: UNIDAD DE FULL PUEBLA | B10: S | C10: 4 | D10: C | E10: MONICAH | F10: 17185 | G10: 46067 | H10: 46067 | I10: 46067 | J10: 46067 | K10: TRA-345 | L10: 00702 | M10: TLAPANCO MORALES, JUAN | N10: WALMART PUEBLA | O10: 6312-HUBP | P10: PUEBLA, PUEBLA | Q10: PUEBLA, PUEBLA | R10: 604379-V | S10: 23289832 | T10: 12.8 | U10: 0 | V10: 604379-V / DOC EN COPIA | W10: 0 | X10: FWP-0241018 | Y10: 429.54 | Z10: 115.71 | AA10: 110.38 | AB10: 203.45 | AC10: 0 | AG10: 1 | AH10: 1 | AI10: 46072.508 | AJ10: ALEJANDRO MENDEZ | AK10: JUAN TLAPANCO MORALES | AL10: 46069.776 | AM10: CARLOSPC | AN10: 335YG4
A11: UNIDAD DE FULL PUEBLA | B11: S | C11: 4 | D11: C | E11: MONICAH | F11: 17187 | G11: 46066 | H11: 46066 | I11: 46067 | J11: 46067 | K11: TRA-241 | L11: 01108 | M11: SANCHEZ RAMIREZ, EDGAR | N11: WALMART PUEBLA | O11: HUBP-6211 | P11: PUEBLA, PUEBLA | Q11: PUEBLA, PUEBLA | R11: 604380-C | S11: 23277301 | T11: 25.3 | U11: 0 | V11: 1306905/1306906 | W11: 0 | X11: FWP-0240809 | Y11: 448.54 | Z11: 229.62 | AA11: 218.92 | AB11: 0 | AC11: 0 | AG11: 0 | AH11: 0 | AL11: 46067.954 | AM11: ALBAAN | AN11: 30UF3S
A12: UNIDAD DE FULL PUEBLA | B12: S | C12: 4 | D12: C | E12: MONICAH | F12: 17189 | G12: 46066 | H12: 46066 | I12: 46067 | J12: 46067 | K12: TRA-241 | L12: 01108 | M12: SANCHEZ RAMIREZ, EDGAR | N12: WALMART PUEBLA | O12: 6211-HUBP | P12: PUEBLA, PUEBLA | Q12: PUEBLA, PUEBLA | R12: 604380-V | S12: 23288800 | T12: 37 | U12: 0 | V12: 604380-V | W12: 0 | X12: FWP-0241413 | Y12: 959.58 | Z12: 334.48 | AA12: 319.07 | AB12: 306.03 | AC12: 0 | AG12: 0 | AH12: 0 | AL12: 46071.987 | AM12: JUANMGC
A13: UNIDAD DE FULL PUEBLA | B13: S | C13: 4 | D13: C | E13: MONICAH | F13: 17196 | G13: 46066 | H13: 46066 | I13: 46067 | J13: 46067 | K13: TRA-241 | L13: 01108 | M13: SANCHEZ RAMIREZ, EDGAR | N13: WALMART PUEBLA | O13: HUBP-6211 | P13: PUEBLA, PUEBLA | Q13: PUEBLA, PUEBLA | R13: 604206-C | S13: 23281950 | T13: 25.3 | U13: 0 | V13: 1306977 | W13: 0 | X13: FWP-0240812 | Y13: 448.54 | Z13: 229.62 | AA13: 218.92 | AB13: 0 | AC13: 0 | AG13: 0 | AH13: 0 | AL13: 46067.955 | AM13: ALBAAN | AN13: 002YC4
A14: UNIDAD DE FULL PUEBLA | B14: S | C14: 4 | D14: C | E14: MONICAH | F14: 17197 | G14: 46066 | H14: 46066 | I14: 46067 | J14: 46067 | K14: TRA-241 | L14: 01108 | M14: SANCHEZ RAMIREZ, EDGAR | N14: WALMART PUEBLA | O14: 6211-HUBP | P14: PUEBLA, PUEBLA | Q14: PUEBLA, PUEBLA | R14: 604206-V | S14: 23288827 | T14: 37 | U14: 0 | V14: 604206-V | W14: 0 | X14: FWP-0241534 | Y14: 959.58 | Z14: 334.48 | AA14: 319.07 | AB14: 306.03 | AC14: 0 | AG14: 0 | AH14: 0 | AL14: 46072.583 | AM14: ALBAAN
A15: UNIDAD DE FULL PUEBLA | B15: S | C15: 4 | D15: C | E15: JESUSG25 | F15: 17325 | G15: 46067 | H15: 46067 | I15: 46067 | J15: 46067 | K15: TRA-214 | L15: 00037 | M15: CAMPOS GARCIA, BOMFILIO | N15: WALMART PUEBLA | O15: HUBP-6312 | P15: PUEBLA, PUEBLA | Q15: PUEBLA, PUEBLA | R15: 604169-C | S15: 23285747 | T15: 14.5 | U15: 0 | V15: 604169-C | W15: 0 | X15: FWP-0240821 | Y15: 431.1 | Z15: 131.08 | AA15: 125.02 | AB15: 175 | AC15: 0 | AD15: 53 | AG15: 1 | AH15: 1 | AI15: 46072.445 | AJ15: ALEJANDRO MENDEZ | AK15: BONIFILIO CAMPOS GARCIA | AL15: 46067.956 | AM15: ALBAAN | AN15: 454YF4
A16: UNIDAD DE FULL PUEBLA | B16: S | C16: 4 | D16: C | E16: JESUSG25 | F16: 17326 | G16: 46067 | H16: 46067 | I16: 46067 | J16: 46067 | K16: TRA-214 | L16: 00037 | M16: CAMPOS GARCIA, BOMFILIO | N16: WALMART PUEBLA | O16: 6312-HUBP | P16: PUEBLA, PUEBLA | Q16: PUEBLA, PUEBLA | R16: 604169-V | S16: 23288792 | T16: 12.8 | U16: 0 | V16: 604169-V | W16: 0 | X16: FWP-0240997 | Y16: 429.54 | Z16: 115.71 | AA16: 110.38 | AB16: 203.45 | AC16: 0 | AD16: 83 | AG16: 1 | AH16: 1 | AI16: 46072.447 | AJ16: ALEJANDRO MENDEZ | AK16: BONIFILIO CAMPOS GARCIA | AL16: 46069.762 | AM16: CARLOSPC | AN16: 454YF4
A17: UNIDAD DE FULL PUEBLA | B17: S | C17: 4 | D17: C | E17: OSCARA | F17: 17458 | G17: 46067 | H17: 46067 | I17: 46067 | J17: 46067 | K17: TRA-341 | L17: 00274 | M17: TEHUITZIL MARTINEZ, JOSE REFUGIO | N17: WALMART PUEBLA | O17: HUBP-ALEN | P17: PUEBLA, PUEBLA | Q17: PUEBLA, PUEBLA | R17: 589867-V | S17: 23288753 | T17: 11.4 | U17: 0 | V17: RECOLECCION | W17: 0 | X17: FWP-0240948 | Y17: 281.22 | Z17: 0.13 | AA17: 106.09 | AB17: 175 | AC17: 0 | AG17: 1 | AH17: 1 | AI17: 46077.778 | AJ17: SILVIA | AK17: REUGIO TEHIUTZILL MARTINEZ | AL17: 46069.704 | AM17: CARLOSPC | AN17: 498YF4
A18: UNIDAD DE FULL PUEBLA | B18: S | C18: 4 | D18: C | E18: OSCARA | F18: 17460 | G18: 46067 | H18: 46067 | I18: 46067 | J18: 46067 | K18: TRA-341 | L18: 00274 | M18: TEHUITZIL MARTINEZ, JOSE REFUGIO | N18: WALMART PUEBLA | O18: ALEN-HUBP | P18: PUEBLA, PUEBLA | Q18: PUEBLA, PUEBLA | R18: 589867-C | S18: 23288760 | T18: 13.1 | U18: 0 | V18: 260302265 | W18: 0 | X18: FWP-0241041 | Y18: 295.96 | Z18: 0.11 | AA18: 92.4 | AB18: 203.45 | AC18: 0 | AG18: 1 | AH18: 1 | AI18: 46077.778 | AJ18: SILVIA | AK18: JOSE REFUGIO TEHUITZIL MARTINEZ | AL18: 46069.899 | AM18: JUANMGC | AN18: 844YG5
A19: UNIDAD DE FULL PUEBLA | B19: S | C19: 4 | D19: C | E19: OSCARA | F19: 17463 | G19: 46067 | H19: 46067 | I19: 46067 | J19: 46067 | K19: TRA-341 | L19: 00274 | M19: TEHUITZIL MARTINEZ, JOSE REFUGIO | N19: WALMART PUEBLA | O19: HUBP-ALEN | P19: PUEBLA, PUEBLA | Q19: PUEBLA, PUEBLA | R19: 589868-V | S19: 23288767 | T19: 11.4 | U19: 0 | V19: RECOLECCION | W19: 0 | X19: FWP-0240949 | Y19: 281.22 | Z19: 0.13 | AA19: 106.09 | AB19: 175 | AC19: 0 | AG19: 1 | AH19: 1 | AI19: 46077.779 | AJ19: SILVIA | AK19: JOSE REFUGIO TEHUTIZIL MARTINEZ | AL19: 46069.705 | AM19: CARLOSPC | AN19: 507YF4
A20: UNIDAD DE FULL PUEBLA | B20: S | C20: 4 | D20: C | E20: OSCARA | F20: 17466 | G20: 46067 | H20: 46067 | I20: 46067 | J20: 46067 | K20: TRA-341 | L20: 00274 | M20: TEHUITZIL MARTINEZ, JOSE REFUGIO | N20: WALMART PUEBLA | O20: ALEN-HUBP | P20: PUEBLA, PUEBLA | Q20: PUEBLA, PUEBLA | R20: 589868-C | S20: 23288783 | T20: 13.1 | U20: 0 | V20: 260302142 | W20: 0 | X20: FWP-0241042 | Y20: 295.96 | Z20: 0.11 | AA20: 92.4 | AB20: 203.45 | AC20: 0 | AG20: 1 | AH20: 1 | AI20: 46077.779 | AJ20: SILVIA | AK20: JOSE REFUGIO TEHUITZIL MARTINEZ | AL20: 46069.899 | AM20: JUANMGC | AN20: 31YA6C
A21: UNIDAD DE FULL PUEBLA | B21: S | C21: 4 | D21: C | E21: JESUSG25 | F21: 17509 | G21: 46067 | H21: 46067 | I21: 46067 | J21: 46067 | K21: TRA-345 | L21: 00702 | M21: TLAPANCO MORALES, JUAN | N21: WALMART PUEBLA | O21: HUBP-6312 | P21: PUEBLA, PUEBLA | Q21: PUEBLA, PUEBLA | R21: 604189-C | S21: 23287065 | T21: 14.5 | U21: 0 | V21: 604189-C / DOC EN COPIA | W21: 0 | X21: FWP-0240823 | Y21: 431.1 | Z21: 131.08 | AA21: 125.02 | AB21: 175 | AC21: 0 | AD21: 55 | AG21: 1 | AH21: 1 | AI21: 46072.494 | AJ21: ALEJANDRO MENDEZ | AK21: JUAN TLAPANCO MORALES | AL21: 46067.957 | AM21: ALBAAN | AN21: 706YF9
A22: UNIDAD DE FULL PUEBLA | B22: S | C22: 4 | D22: C | E22: JESUSG25 | F22: 17510 | G22: 46067 | H22: 46067 | I22: 46067 | J22: 46067 | K22: TRA-345 | L22: 00702 | M22: TLAPANCO MORALES, JUAN | N22: WALMART PUEBLA | O22: 6312-HUBP | P22: PUEBLA, PUEBLA | Q22: PUEBLA, PUEBLA | R22: 604189-V | S22: 23289767 | T22: 12.8 | U22: 0 | V22: 604189-V / DOC EN COPIA | W22: 0 | X22: FWP-0241001 | Y22: 429.54 | Z22: 115.71 | AA22: 110.38 | AB22: 203.45 | AC22: 0 | AD22: 60 | AG22: 1 | AH22: 1 | AI22: 46072.494 | AJ22: ALEJANDRO MENDEZ | AK22: JUAN TLAPANCO MORALES | AL22: 46069.771 | AM22: CARLOSPC | AN22: 706YF9
A23: UNIDAD DE FULL PUEBLA | B23: S | C23: 4 | D23: C | E23: OSCARA | F23: 18921 | G23: 46068 | H23: 46068 | I23: 46068 | J23: 46068 | K23: TRA-341 | L23: 00274 | M23: TEHUITZIL MARTINEZ, JOSE REFUGIO | N23: WALMART PUEBLA | O23: HUBP-ALEN | P23: PUEBLA, PUEBLA | Q23: PUEBLA, PUEBLA | R23: 585709-V | S23: 23299041 | T23: 11.4 | U23: 0 | V23: RECOLECCION | W23: 0 | X23: FWP-0241222 | Y23: 281.23 | Z23: 0.13 | AA23: 106.1 | AB23: 175 | AC23: 0 | AG23: 1 | AH23: 1 | AI23: 46078.704 | AJ23: ALEJANDRO MENDEZ | AK23: JOSE REFUGIO TEHUITZIL MARTINEZ | AL23: 46071.538 | AM23: CARLOSPC | AN23: 992YC7
A24: UNIDAD DE FULL PUEBLA | B24: S | C24: 4 | D24: C | E24: OSCARA | F24: 18924 | G24: 46068 | H24: 46068 | I24: 46068 | J24: 46068 | K24: TRA-341 | L24: 00274 | M24: TEHUITZIL MARTINEZ, JOSE REFUGIO | N24: WALMART PUEBLA | O24: ALEN-HUBP | P24: PUEBLA, PUEBLA | Q24: PUEBLA, PUEBLA | R24: 585709-C | S24: 23299049 | T24: 13.1 | U24: 0 | V24: 260302340 | W24: 0 | X24: FWP-0241366 | Y24: 295.96 | Z24: 0.11 | AA24: 92.4 | AB24: 203.45 | AC24: 0 | AG24: 1 | AH24: 1 | AI24: 46078.704 | AJ24: ALEJANDRO MENDEZ | AK24: JOSE REFUGIO TEHUITZIL MARTINEZ | AL24: 46071.929 | AM24: JUANMGC | AN24: 29YA4H
A25: UNIDAD DE FULL PUEBLA | B25: S | C25: 4 | D25: C | E25: OSCARA | F25: 18925 | G25: 46068 | H25: 46068 | I25: 46068 | J25: 46068 | K25: TRA-341 | L25: 00274 | M25: TEHUITZIL MARTINEZ, JOSE REFUGIO | N25: WALMART PUEBLA | O25: HUBP-ALEN | P25: PUEBLA, PUEBLA | Q25: PUEBLA, PUEBLA | R25: 585710-V | S25: 23298953 | T25: 11.4 | U25: 0 | V25: RECOLECCION | W25: 0 | X25: FWP-0241218 | Y25: 281.23 | Z25: 0.13 | AA25: 106.1 | AB25: 175 | AC25: 0 | AG25: 1 | AH25: 1 | AI25: 46078.708 | AJ25: ALEJANDRO MENDEZ | AK25: JOSE REFUGIO TEHUITZIL MARTINEZ | AL25: 46071.538 | AM25: CARLOSPC | AN25: 555YG1
A26: UNIDAD DE FULL PUEBLA | B26: S | C26: 4 | D26: C | E26: OSCARA | F26: 18928 | G26: 46068 | H26: 46068 | I26: 46068 | J26: 46068 | K26: TRA-341 | L26: 00274 | M26: TEHUITZIL MARTINEZ, JOSE REFUGIO | N26: WALMART PUEBLA | O26: ALEN-HUBP | P26: PUEBLA, PUEBLA | Q26: PUEBLA, PUEBLA | R26: 585710-C | S26: 23298979 | T26: 13.1 | U26: 0 | V26: 260302276 | W26: 0 | X26: FWP-0241362 | Y26: 295.96 | Z26: 0.11 | AA26: 92.4 | AB26: 203.45 | AC26: 0 | AG26: 1 | AH26: 1 | AI26: 46078.708 | AJ26: ALEJANDRO MENDEZ | AK26: JOSE REFUGIO TEHUITZIL MARTINEZ | AL26: 46071.929 | AM26: JUANMGC | AN26: 46YA9C
A27: UNIDAD DE FULL PUEBLA | B27: S | C27: 4 | D27: C | E27: ELIZABETH | F27: 17951 | G27: 46069 | H27: 46069 | I27: 46069 | J27: 46069 | K27: TRA-287 | L27: 01772 | M27: ROJAS MENDIETA, ADRIAN | N27: WALMART PUEBLA | O27: HUBP-1276 | P27: PUEBLA, PUEBLA | Q27: ACAJETE, PUEBLA | R27: 604906-C | S27: 23295059 | T27: 36.2 | U27: 0 | V27: 1308994 | W27: 0 | X27: FWP-0240940 | Y27: 897.69 | Z27: 327.25 | AA27: 319.58 | AB27: 250.86 | AC27: 0 | AD27: 22 | AG27: 1 | AH27: 1 | AI27: 46078.4 | AJ27: ALEJANDRO MENDEZ | AK27: ADRIAN ROJAS MENDIETA | AL27: 46069.693 | AM27: ELIZAPALE | AN27: 668YD7
A28: UNIDAD DE FULL PUEBLA | B28: S | C28: 4 | D28: C | E28: ELIZABETH | F28: 17952 | G28: 46069 | H28: 46069 | I28: 46069 | J28: 46069 | K28: TRA-287 | L28: 01772 | M28: ROJAS MENDIETA, ADRIAN | N28: WALMART PUEBLA | O28: 1276-HUBP | P28: ACAJETE, PUEBLA | Q28: PUEBLA, PUEBLA | R28: 604906-V | S28: 23297628 | T28: 34.3 | U28: 0 | V28: 604906-V | W28: 0 | X28: FWP-0241127 | Y28: 945.55 | Z28: 310.07 | AA28: 302.72 | AB28: 332.76 | AC28: 0 | AD28: 9 | AG28: 1 | AH28: 1 | AI28: 46078.4 | AJ28: ALEJANDRO MENDEZ | AK28: ADRIAN ROJAS MENDIETA | AL28: 46070.69 | AM28: CARLOSPC | AN28: 668YD7
A29: UNIDAD DE FULL PUEBLA | B29: S | C29: 4 | D29: C | E29: ELIZABETH | F29: 18010 | G29: 46069 | H29: 46069 | I29: 46069 | J29: 46069 | K29: TRA-287 | L29: 01772 | M29: ROJAS MENDIETA, ADRIAN | N29: WALMART PUEBLA | O29: HUBP-1801 | P29: PUEBLA, PUEBLA | Q29: PUEBLA, PUEBLA | R29: 604907-C | S29: 23294895 | T29: 18.1 | U29: 0 | V29: 1308957/3318871 / DOC EN COPIA | W29: 0 | X29: FWP-0241080 | Y29: 408.01 | Z29: 208.82 | AA29: 199.19 | AB29: 0 | AC29: 0 | AD29: 12 | AG29: 1 | AH29: 1 | AI29: 46077.77 | AJ29: ALEJANDRO MENDEZ | AK29: ADRIAN ROJAS MENDIETA | AL29: 46070.682 | AM29: ELIZAPALE | AN29: 821YG5
A30: UNIDAD DE FULL PUEBLA | B30: S | C30: 4 | D30: C | E30: ELIZABETH | F30: 18011 | G30: 46069 | H30: 46069 | I30: 46069 | J30: 46069 | K30: TRA-287 | L30: 01772 | M30: ROJAS MENDIETA, ADRIAN | N30: WALMART PUEBLA | O30: 1801-HUBP | P30: PUEBLA, PUEBLA | Q30: PUEBLA, PUEBLA | R30: 604907-V | S30: 23303090 | T30: 15.7 | U30: 0 | V30: 604907-V / DOC EN COPIA | W30: 0 | X30: FWP-0241261 | Y30: 310.86 | Z30: 159.1 | AA30: 151.76 | AB30: 0 | AC30: 0 | AD30: 11 | AG30: 1 | AH30: 1 | AI30: 46077.77 | AJ30: ALEJANDRO MENDEZ | AK30: ADRIAN ROJAS MENDIETA | AL30: 46071.67 | AM30: ALBAAN | AN30: 84UJ7J
A31: UNIDAD DE FULL PUEBLA | B31: S | C31: 4 | D31: C | E31: ELIZABETH | F31: 18024 | G31: 46069 | H31: 46069 | I31: 46069 | J31: 46069 | K31: TRA-287 | L31: 01772 | M31: ROJAS MENDIETA, ADRIAN | N31: WALMART PUEBLA | O31: HUBP-3853 | P31: PUEBLA, PUEBLA | Q31: PUEBLA, PUEBLA | R31: 604029-C | S31: 23294392 | T31: 17 | U31: 0 | V31: 1308951/3318867 / DOC EN COPIA | W31: 0 | X31: FWP-0241021 | Y31: 478.72 | Z31: 155.49 | AA31: 148.23 | AB31: 175 | AC31: 0 | AD31: 7 | AG31: 1 | AH31: 1 | AI31: 46078.441 | AJ31: ALEJANDRO MENDEZ | AK31: ADRIAN ROJAS MENDIETA | AL31: 46069.779 | AM31: ELIZAPALE | AN31: 948YG3
A32: UNIDAD DE FULL PUEBLA | B32: S | C32: 4 | D32: C | E32: ELIZABETH | F32: 18025 | G32: 46069 | H32: 46069 | I32: 46069 | J32: 46069 | K32: TRA-287 | L32: 01772 | M32: ROJAS MENDIETA, ADRIAN | N32: WALMART PUEBLA | O32: 3853-HUBP | P32: PUEBLA, PUEBLA | Q32: PUEBLA, PUEBLA | R32: 604029-V | S32: 23301356 | T32: 16 | U32: 0 | V32: 604029-V / DOC EN COPIA | W32: 0 | X32: FWP-0241242 | Y32: 489.5 | Z32: 146.45 | AA32: 139.6 | AB32: 203.45 | AC32: 0 | AD32: 5 | AG32: 1 | AH32: 1 | AI32: 46078.441 | AJ32: ALEJANDRO MENDEZ | AK32: ADRIAN ROJAS MENDIETA | AL32: 46071.666 | AM32: ALBAAN | AN32: 72UJ6J
A33: UNIDAD DE FULL PUEBLA | B33: S | C33: 4 | D33: C | E33: ELIZABETH | F33: 18073 | G33: 46069 | H33: 46069 | I33: 46069 | J33: 46069 | K33: TRA-287 | L33: 01772 | M33: ROJAS MENDIETA, ADRIAN | N33: WALMART PUEBLA | O33: HUBP-3864 | P33: PUEBLA, PUEBLA | Q33: PUEBLA, PUEBLA | R33: 604936-C | S33: 23296848 | T33: 8.8 | U33: 0 | V33: 1307621/3317951 / DOC EN COPIA | W33: 0 | X33: FWP-0241069 | Y33: 155.43 | Z33: 79.55 | AA33: 75.88 | AB33: 0 | AC33: 0 | AD33: 9 | AG33: 1 | AH33: 1 | AI33: 46078.433 | AJ33: ALEJANDRO MENDEZ | AK33: ADRIAN ROJAS MENDIETA | AL33: 46070.488 | AM33: ELIZAPALE | AN33: 160YF9
A34: UNIDAD DE FULL PUEBLA | B34: S | C34: 4 | D34: C | E34: ELIZABETH | F34: 18074 | G34: 46069 | H34: 46069 | I34: 46069 | J34: 46069 | K34: TRA-287 | L34: 01772 | M34: ROJAS MENDIETA, ADRIAN | N34: WALMART PUEBLA | O34: 3864-HUBP | P34: PUEBLA, PUEBLA | Q34: PUEBLA, PUEBLA | R34: 604936-V | S34: 23302085 | T34: 7.8 | U34: 0 | V34: 604936-V / DOC EN COPIA | W34: 0 | X34: FWP-0241253 | Y34: 176.63 | Z34: 90.4 | AA34: 86.23 | AB34: 0 | AC34: 0 | AD34: 12 | AG34: 1 | AH34: 1 | AI34: 46078.434 | AJ34: ALEJANDRO MENDEZ | AK34: ADRIAN ROJAS MENDIETA | AL34: 46071.669 | AM34: ALBAAN | AN34: 917YG3
A35: UNIDAD DE FULL PUEBLA | B35: S | C35: 4 | D35: C | E35: ALMAVIVAS | F35: 18450 | G35: 46069 | H35: 46069 | I35: 46069 | J35: 46069 | K35: TRA-287 | L35: 01772 | M35: ROJAS MENDIETA, ADRIAN | N35: WALMART PUEBLA | O35: HUBP-4988 | P35: PUEBLA, PUEBLA | Q35: CHOLULA, PUEBLA | R35: 604876-C | S35: 23298547 | T35: 13.4 | U35: 0 | V35: 1309756 / DOC EN COPIA | W35: 0 | X35: FWP-0241078 | Y35: 236.69 | Z35: 121.14 | AA35: 115.55 | AB35: 0 | AC35: 0 | AD35: 15 | AG35: 1 | AH35: 1 | AI35: 46078.419 | AJ35: ALEJANDRO MENDEZ | AK35: ADRIAN ROJAS MENDIETA | AL35: 46070.681 | AM35: ELIZAPALE | AN35: 862YF8
A36: UNIDAD DE FULL PUEBLA | B36: S | C36: 4 | D36: C | E36: ALMAVIVAS | F36: 18452 | G36: 46069 | H36: 46069 | I36: 46069 | J36: 46069 | K36: TRA-287 | L36: 01772 | M36: ROJAS MENDIETA, ADRIAN | N36: WALMART PUEBLA | O36: 4988-HUBP | P36: CHOLULA, PUEBLA | Q36: PUEBLA, PUEBLA | R36: 604876-V | S36: 23303114 | T36: 18.3 | U36: 0 | V36: 604876-V / DOC EN COPIA | W36: 0 | X36: FWP-0241262 | Y36: 323.23 | Z36: 165.43 | AA36: 157.8 | AB36: 0 | AC36: 0 | AD36: 13 | AG36: 1 | AH36: 1 | AI36: 46078.419 | AJ36: ALEJANDRO MENDEZ | AK36: ADRIAN ROJAS MENDIETA | AL36: 46071.67 | AM36: ALBAAN | AN36: 547YG1
A37: UNIDAD DE FULL PUEBLA | B37: S | C37: 4 | D37: C | E37: OSCARA | F37: 18929 | G37: 46069 | H37: 46069 | I37: 46069 | J37: 46069 | K37: TRA-341 | L37: 00274 | M37: TEHUITZIL MARTINEZ, JOSE REFUGIO | N37: WALMART PUEBLA | O37: HUBP-ALEN | P37: PUEBLA, PUEBLA | Q37: PUEBLA, PUEBLA | R37: 585711-V | S37: 23298987 | T37: 11.4 | U37: 0 | V37: RECOLECCION | W37: 0 | X37: FWP-0241219 | Y37: 281.23 | Z37: 0.13 | AA37: 106.1 | AB37: 175 | AC37: 0 | AD37: 76 | AG37: 1 | AH37: 1 | AI37: 46078.722 | AJ37: ALEJANDRO MENDEZ | AK37: JOSE REFUGIO TEHUITZIL MARTINEZ | AL37: 46071.538 | AM37: CARLOSPC | AN37: 27YA4H
A38: UNIDAD DE FULL PUEBLA | B38: S | C38: 4 | D38: C | E38: OSCARA | F38: 18930 | G38: 46069 | H38: 46069 | I38: 46069 | J38: 46069 | K38: TRA-341 | L38: 00274 | M38: TEHUITZIL MARTINEZ, JOSE REFUGIO | N38: WALMART PUEBLA | O38: ALEN-HUBP | P38: PUEBLA, PUEBLA | Q38: PUEBLA, PUEBLA | R38: 585711-C | S38: 23298997 | T38: 13.1 | U38: 0 | V38: 260302278 | W38: 0 | X38: FWP-0241363 | Y38: 295.96 | Z38: 0.11 | AA38: 92.4 | AB38: 203.45 | AC38: 0 | AD38: 73 | AG38: 1 | AH38: 1 | AI38: 46078.722 | AJ38: ALEJANDRO MENDEZ | AK38: JOSE REFUGIO TEHUITZIL MARTINEZ | AL38: 46071.929 | AM38: JUANMGC | AN38: 992YC7
A39: UNIDAD DE FULL PUEBLA | B39: S | C39: 4 | D39: C | E39: OSCARA | F39: 18931 | G39: 46069 | H39: 46069 | I39: 46069 | J39: 46069 | K39: TRA-341 | L39: 00274 | M39: TEHUITZIL MARTINEZ, JOSE REFUGIO | N39: WALMART PUEBLA | O39: HUBP-ALEN | P39: PUEBLA, PUEBLA | Q39: PUEBLA, PUEBLA | R39: 585712-V | S39: 23299004 | T39: 11.4 | U39: 0 | V39: RECOLECCION | W39: 0 | X39: FWP-0241220 | Y39: 281.23 | Z39: 0.13 | AA39: 106.1 | AB39: 175 | AC39: 0 | AG39: 1 | AH39: 1 | AI39: 46078.722 | AJ39: ALEJANDRO MENDEZ | AK39: JOSE REFUGIO TEHUITZIL MARTINEZ | AL39: 46071.538 | AM39: CARLOSPC | AN39: 40UH9X
A40: UNIDAD DE FULL PUEBLA | B40: S | C40: 4 | D40: C | E40: OSCARA | F40: 18932 | G40: 46069 | H40: 46069 | I40: 46069 | J40: 46069 | K40: TRA-341 | L40: 00274 | M40: TEHUITZIL MARTINEZ, JOSE REFUGIO | N40: WALMART PUEBLA | O40: ALEN-HUBP | P40: PUEBLA, PUEBLA | Q40: PUEBLA, PUEBLA | R40: 585712-C | S40: 23299016 | T40: 13.1 | U40: 0 | V40: 260302279 | W40: 0 | X40: FWP-0241364 | Y40: 295.96 | Z40: 0.11 | AA40: 92.4 | AB40: 203.45 | AC40: 0 | AG40: 1 | AH40: 1 | AI40: 46078.722 | AJ40: ALEJANDRO MENDEZ | AK40: JOSE REFUGIO TEHUITZIL MARTINEZ | AL40: 46071.929 | AM40: JUANMGC | AN40: 555YG1
...

Sheet RESUMEN 1
B2: UNIDADES FULL EN VIAJES SENCILLOS
B3: UNIDAD | C3: VIAJES SENCILLOS CARGADOS | D3: COMENTARIOS
B4: TRA-341 | C4: 18 | D4: UNIDAD DE MULITAS PUEBLA
B5: TRA-214 | C5: 2 | D5: UNIDAD DE MULITAS PUEBLA
B6: TRA-345 | C6: 2 | D6: UNIDAD DE MULITAS PUEBLA
B7: TRA-241 | C7: 8 | D7: UNIDAD DE MULITAS PUEBLA
B8: TRA-287 | C8: 37 | D8: UNIDAD DE MULITAS PUEBLA
B9: TRA-263 | C9: 2 | D9: UNIDAD DE MULITAS PUEBLA
B10: TRA-284 | C10: 1 | D10: UNIDAD DE MULITAS PUEBLA
B11: TRA-307 | C11: 4 | D11: UNIDAD DE MULITAS PUEBLA
B12: TRA-163 | C12: 1 | D12: UNIDAD DE MULITAS PUEBLA
B13: TRA-271 | C13: 2 | D13: UNIDAD DE MULITAS PUEBLA
B14: TOC-45 | C14: 4 | D14: UNIDAD DE MULITAS PUEBLA
B15: TOC-39 | C15: 4 | D15: UNIDAD DE MULITAS PUEBLA
... B20: TRA-157 | C20: 2 | D20: UNIDAD DE MULITAS PUEBLA
A21: TOTALES | B21: 17 | C21: 99
F24: FOTO COMPARTIDA DE POOL PUEBLA SENCILLOS

Sheet S-FULL
A1: UNIDADES DE SENCILLO HACIENDO VIAJES DE FULL 12-02-2026 AL DIA 26-02-2026
A2: Columna libre | B2: TipoRemolque | C2: NumFase | D2: Status | E2: Viajes.CrUsuario | F2: ID | G2: FechaProgCarga | H2: FechaRealCarga | I2: FechaInicioReal | J2: FechaRealDescarga | K2: ID_Tractor | L2: ID_Operador | M2: Operadores.Descripcion | N2: Clientes.Descripcion | O2: ID_Ruta | P2: Origen | Q2: Destino | R2: Numremision | S2: NumCarga | T2: Kilometros | U2: ImporteFlete | V2: Observaciones | W2: ImporteManiobras | X2: ID_Factura | Y2: ImporteFacturado | Z2: ImporteOtros1 | AA2: ImporteOtros2 | AB2: ImporteAutopistas | AC2: ImporteSeguro | AD2: TotLitros | AE2: ID_Permisionario | AF2: ImporteTotal | AG2: DocumentacionViajeRecibida | AH2: DocumentacionCorrecta | AI2: FechaRecepcionDoctos | AJ2: UsuarioRecibioDoctos | AK2: UsuarioEntregoDoctos | AL2: FechaSeFacturo | AM2: facturas.CrUsuario | AN2: DescripcionRemolque1 | AO2: DescripcionRemolque2
A3: NO ESTA EN POOL PÉRO ES DE F PUEBLA | B3: F | C3: 4 | D3: C | E3: MROCIO | F3: 16530 | G3: 46065 | H3: 46065 | I3: 46065 | J3: 46065 | K3: TRA-321 | L3: 00622 | M3: CASOLCO ZARCO, CARLOS ALEJANDRO | N3: WALMART PUEBLA | O3: HUBP-CDCH | P3: PUEBLA, PUEBLA | Q3: CHALCO DE DIAZ COVARRUBIAS, EDO. DE MEXICO | R3: 604407-V | S3: 23281995 | T3: 96.4 | U3: 0 | V3: 604407-V/ SIN HOJA DE ID | W3: 0 | X3: FWP-0240953 | Y3: 2769.99 | Z3: 617.92 | AA3: 1122.76 | AB3: 1029.31 | AC3: 0 | AD3: 81 | AG3: 1 | AH3: 1 | AI3: 46072.501 | AJ3: OSCAR GONZALEZ | AK3: CARLOS ALEJANDRO CASOLCO ZARCO | AL3: 46069.719 | AM3: CARLOSPC | AN3: 06UG8M | AO3: 334YG4 | AP3: =IF(ISNUMBER(FIND("C",R3)),"C","V") -> V
A4: NO ESTA EN POOL PÉRO ES DE F PUEBLA | B4: F | C4: 4 | D4: C | E4: MROCIO | F4: 16529 | G4: 46065 | H4: 46065.125 | I4: 46065.125 | J4: 46065.375 | K4: TRA-321 | L4: 00622 | M4: CASOLCO ZARCO, CARLOS ALEJANDRO | N4: WALMART PUEBLA | O4: CDCH-HUBP | P4: CHALCO DE DIAZ COVARRUBIAS, EDO. DE MEXICO | Q4: CUAUTLANCINGO, PUEBLA | R4: 604407-C | S4: 23272438 | T4: 97.5 | U4: 0 | V4: 1306370-3315389-1306369 | W4: 0 | X4: FWCH-0115429 | Y4: 2797.84 | Z4: 624.98 | AA4: 1143.55 | AB4: 1029.31 | AC4: 0 | AD4: 159 | AG4: 1 | AH4: 1 | AI4: 46072.499 | AJ4: OSCAR GONZALEZ | AK4: CARLOS ALEJANDRO CASOLCO ZARCO | AL4: 46065.474 | AM4: SILVIA | AN4: 34UF3S | AO4: 71YA8M | AP4: =IF(ISNUMBER(FIND("C",R4)),"C","V") -> C
A5: NO ESTA EN POOL PÉRO ES DE F PUEBLA | B5: F | C5: 3 | D5: A | E5: CMARTINEZ | F5: 17361 | G5: 46067 | H5: 46067 | I5: 46067 | J5: 46067 | K5: TRA-238 | L5: 01469 | M5: LOPEZ GARCIA, ARTURO JESUS | N5: WALMART PUEBLA | O5: CDCH-HUBP | P5: CHALCO DE DIAZ COVARRUBIAS, EDO. DE MEXICO | Q5: CUAUTLANCINGO, PUEBLA | R5: 604116-C | S5: 23288990 | T5: 97.5 | U5: 0 | V5: 1308854-3317089-1309135-3318047 | W5: 0 | X5: FWP-0241038 | Y5: 2797.77 | Z5: 624.98 | AA5: 1143.48 | AB5: 1029.31 | AC5: 0 | AG5: 1 | AH5: 1 | AI5: 46076.446 | AJ5: ALEJANDRO MENDEZ | AK5: ARTURO JESUS LOPEZ GARCIA | AL5: 46069.899 | AM5: JUANMGC | AN5: 50UF3S | AO5: 891XT7 | AP5: =IF(ISNUMBER(FIND("C",R5)),"C","V") -> C
A6: NO ESTA EN POOL PÉRO ES DE F PUEBLA | B6: F | C6: 3 | D6: A | E6: CMARTINEZ | F6: 17362 | G6: 46067 | H6: 46067 | I6: 46067 | J6: 46067 | K6: TRA-238 | L6: 01469 | M6: LOPEZ GARCIA, ARTURO JESUS | N6: WALMART PUEBLA | O6: HUBP-CDCH | P6: PUEBLA, PUEBLA | Q6: CHALCO DE DIAZ COVARRUBIAS, EDO. DE MEXICO | R6: 604116-V | S6: 23293444 | T6: 96.4 | U6: 0 | W6: 0 | X6: FWP-0241436 | Y6: 2770.15 | Z6: 617.92 | AA6: 1122.92 | AB6: 1029.31 | AC6: 0 | AG6: 1 | AH6: 1 | AI6: 46076.721 | AJ6: ALEJANDRO MENDEZ | AK6: ARTURO JESUS LOPEZ GARCIA | AL6: 46072.09 | AM6: JUANMGC | AP6: =IF(ISNUMBER(FIND("C",R6)),"C","V") -> V
A7: FULL CORDOBA | B7: F | C7: 4 | D7: C | E7: CMARTINEZ | F7: 17403 | G7: 46067 | H7: 46067 | I7: 46067 | J7: 46067 | K7: TRA-255 | L7: 01875 | M7: SANTANA LEON, SERGIO | N7: WALMART PUEBLA | O7: HUBP-CDCH | P7: PUEBLA, PUEBLA | Q7: CHALCO DE DIAZ COVARRUBIAS, EDO. DE MEXICO | R7: 604129-V | S7: 23293476 | T7: 96.4 | U7: 0 | W7: 0 | X7: FWP-0241438 | Y7: 2770.15 | Z7: 617.92 | AA7: 1122.92 | AB7: 1029.31 | AC7: 0 | AD7: 86 | AG7: 1 | AH7: 1 | AI7: 46076.72 | AJ7: ALEJANDRO MENDEZ | AK7: SERGIO SANTANA LEON | AL7: 46072.09 | AM7: JUANMGC | AP7: =IF(ISNUMBER(FIND("C",R7)),"C","V") -> V
A8: FULL CORDOBA | B8: F | C8: 4 | D8: C | E8: CMARTINEZ | F8: 17401 | G8: 46067 | H8: 46067.125 | I8: 46067.125 | J8: 46067.375 | K8: TRA-255 | L8: 01875 | M8: SANTANA LEON, SERGIO | N8: WALMART PUEBLA | O8: CDCH-HUBP | P8: CHALCO DE DIAZ COVARRUBIAS, EDO. DE MEXICO | Q8: CUAUTLANCINGO, PUEBLA | R8: 604129-C | S8: 23289210 | T8: 97.5 | U8: 0 | V8: 1308546-1308547-1308501-1308502 | W8: 0 | X8: FWCH-0115675 | Y8: 2797.77 | Z8: 624.98 | AA8: 1143.48 | AB8: 1029.31 | AC8: 0 | AD8: 135 | AG8: 1 | AH8: 1 | AI8: 46076.437 | AJ8: ALEJANDRO MENDEZ | AK8: SERGIO SANTANA LEON | AL8: 46067.659 | AM8: CARLOSPC | AN8: 59UH9X | AO8: 661XT7 | AP8: =IF(ISNUMBER(FIND("C",R8)),"C","V") -> C
A9: FULL CORDOBA | B9: F | C9: 4 | D9: C | E9: CMARTINEZ | F9: 17746 | G9: 46068 | H9: 46068 | I9: 46068 | J9: 46068 | K9: TRA-330 | L9: 01649 | M9: MUÑOZ AMAYO, GABRIEL | N9: WALMART PUEBLA | O9: HUBP-CDCH | P9: PUEBLA, PUEBLA | Q9: CHALCO DE DIAZ COVARRUBIAS, EDO. DE MEXICO | R9: 604011-V | S9: 23299675 | T9: 96.4 | U9: 0 | W9: 0 | X9: FWP-0241450 | Y9: 2770.08 | Z9: 617.92 | AA9: 1122.85 | AB9: 1029.31 | AC9: 0 | AG9: 0 | AH9: 0 | AI9: 46071.708 | AJ9: . | AK9: . | AL9: 46072.099 | AM9: JUANMGC | AP9: =IF(ISNUMBER(FIND("C",R9)),"C","V") -> V
A10: FULL CORDOBA | B10: F | C10: 4 | D10: C | E10: CMARTINEZ | F10: 17785 | G10: 46068 | H10: 46068 | I10: 46068 | J10: 46068 | K10: TRA-369 | L10: 01849 | M10: PONCE GALINDO, SANTOS | N10: WALMART PUEBLA | O10: HUBP-CDCH | P10: PUEBLA, PUEBLA | Q10: CHALCO DE DIAZ COVARRUBIAS, EDO. DE MEXICO | R10: 604031-V | S10: 23299809 | T10: 96.4 | U10: 0 | W10: 0 | X10: FWP-0241458 | Y10: 2770.08 | Z10: 617.92 | AA10: 1122.85 | AB10: 1029.31 | AC10: 0 | AG10: 1 | AH10: 1 | AI10: 46077.704 | AJ10: ALEJANDRO MENDEZ | AK10: SANTOS PONCE GALINDO | AL10: 46072.101 | AM10: JUANMGC | AP10: =IF(ISNUMBER(FIND("C",R10)),"C","V") -> V
A11: NO ESTA EN POOL PÉRO ES DE F PUEBLA | B11: F | C11: 4 | D11: C | E11: CMARTINEZ | F11: 17797 | G11: 46068 | H11: 46068 | I11: 46068 | J11: 46068 | K11: TRA-321 | L11: 00622 | M11: CASOLCO ZARCO, CARLOS ALEJANDRO | N11: WALMART PUEBLA | O11: HUBP-CDCH | P11: PUEBLA, PUEBLA | Q11: CHALCO DE DIAZ COVARRUBIAS, EDO. DE MEXICO | R11: 604037-V | S11: 23299784 | T11: 96.4 | U11: 0 | W11: 0 | X11: FWP-0241455 | Y11: 2770.08 | Z11: 617.92 | AA11: 1122.85 | AB11: 1029.31 | AC11: 0 | AD11: 81 | AG11: 1 | AH11: 1 | AI11: 46077.706 | AJ11: ALEJANDRO MENDEZ | AK11: CARLOS ALEJANDRO CASOLCO ZARCO | AL11: 46072.101 | AM11: JUANMGC | AP11: =IF(ISNUMBER(FIND("C",R11)),"C","V") -> V
A12: FULL CORDOBA | B12: F | C12: 4 | D12: C | E12: CMARTINEZ | F12: 17825 | G12: 46068 | H12: 46068 | I12: 46068 | J12: 46068 | K12: TOC-358 | L12: 01179 | M12: GARCIA PICHARDO, JESUS EUGENIO | N12: WALMART PUEBLA | O12: HUBP-CDCH | P12: PUEBLA, PUEBLA | Q12: CHALCO DE DIAZ COVARRUBIAS, EDO. DE MEXICO | R12: 604930-V | S12: 23299966 | T12: 96.4 | U12: 0 | W12: 0 | X12: FWP-0241461 | Y12: 2770.08 | Z12: 617.92 | AA12: 1122.85 | AB12: 1029.31 | AC12: 0 | AG12: 1 | AH12: 1 | AI12: 46077.703 | AJ12: ALEJANDRO MENDEZ | AK12: JESUS EUGENIO GARCIA PICHARDO | AL12: 46072.102 | AM12: JUANMGC | AO12: XXXX | AP12: =IF(ISNUMBER(FIND("C",R12)),"C","V") -> V
A13: FULL CORDOBA | B13: F | C13: 4 | D13: C | E13: MROCIO | F13: 17968 | G13: 46068 | H13: 46068 | I13: 46068 | J13: 46068 | K13: TRA-255 | L13: 01875 | M13: SANTANA LEON, SERGIO | N13: WALMART PUEBLA | O13: HUBP-CDCH | P13: PUEBLA, PUEBLA | Q13: CHALCO DE DIAZ COVARRUBIAS, EDO. DE MEXICO | R13: 604941-V | S13: 23300170 | T13: 96.4 | U13: 0 | W13: 0 | X13: FWP-0241469 | Y13: 2770.08 | Z13: 617.92 | AA13: 1122.85 | AB13: 1029.31 | AC13: 0 | AD13: 90 | AG13: 1 | AH13: 1 | AI13: 46076.7 | AJ13: ALEJANDRO MENDEZ | AK13: SERGIO SANTANA LEON | AL13: 46072.103 | AM13: JUANMGC | AP13: =IF(ISNUMBER(FIND("C",R13)),"C","V") -> V
A14: FULL CORDOBA | B14: F | C14: 4 | D14: C | E14: MROCIO | F14: 17970 | G14: 46068 | H14: 46068 | I14: 46068 | J14: 46068 | K14: TRA-252 | L14: 00796 | M14: VARGAS MARTINEZ, ERIK JULIO | N14: WALMART PUEBLA | O14: HUBP-CDCH | P14: PUEBLA, PUEBLA | Q14: CHALCO DE DIAZ COVARRUBIAS, EDO. DE MEXICO | R14: 604944-V | S14: 23300167 | T14: 96.4 | U14: 0 | W14: 0 | X14: FWP-0241468 | Y14: 2770.08 | Z14: 617.92 | AA14: 1122.85 | AB14: 1029.31 | AC14: 0 | AD14: 84 | AG14: 1 | AH14: 1 | AI14: 46076.7 | AJ14: ALEJANDRO MENDEZ | AK14: ERIK JULIO VARGAS MARTINEZ | AL14: 46072.103 | AM14: JUANMGC | AP14: =IF(ISNUMBER(FIND("C",R14)),"C","V") -> V
A15: CUAUTI | B15: F | C15: 3 | D15: A | E15: MROCIO | F15: 17972 | G15: 46068 | H15: 46068 | I15: 46068 | J15: 46068 | K15: TOC-35 | L15: 00141 | M15: JIMENEZ DIAZ, VICTOR MANUEL | N15: WALMART PUEBLA | O15: HUBP-CDCH | P15: PUEBLA, PUEBLA | Q15: CHALCO DE DIAZ COVARRUBIAS, EDO. DE MEXICO | R15: 604947-V | S15: 23300164 | T15: 96.4 | U15: 0 | W15: 0 | X15: FWP-0241467 | Y15: 2770.08 | Z15: 617.92 | AA15: 1122.85 | AB15: 1029.31 | AC15: 0 | AD15: 41 | AG15: 1 | AH15: 1 | AI15: 46076.7 | AJ15: ALEJANDRO MENDEZ | AK15: VICTOR AMNUEL JIMENEZ DIAZ | AL15: 46072.103 | AM15: JUANMGC | AN15: XXXX | AO15: XXXX | AP15: =IF(ISNUMBER(FIND("C",R15)),"C","V") -> V
A16: FULL CORDOBA | B16: F | C16: 4 | D16: C | E16: CMARTINEZ | F16: 17745 | G16: 46068 | H16: 46068.125 | I16: 46068.125 | J16: 46068.375 | K16: TRA-330 | L16: 01649 | M16: MUÑOZ AMAYO, GABRIEL | N16: WALMART PUEBLA | O16: CDCH-HUBP | P16: CHALCO DE DIAZ COVARRUBIAS, EDO. DE MEXICO | Q16: CUAUTLANCINGO, PUEBLA | R16: 604011-C | S16: 23293423 | T16: 97.5 | U16: 0 | V16: 1308936-1308937 | W16: 0 | X16: FWCH-0115707 | Y16: 2797.82 | Z16: 624.98 | AA16: 1143.53 | AB16: 1029.31 | AC16: 0 | AG16: 0 | AH16: 0 | AL16: 46068.426 | AM16: JUANMGC | AN16: 355YG5 | AO16: 44UJ6J | AP16: =IF(ISNUMBER(FIND("C",R16)),"C","V") -> C
A17: FULL CORDOBA | B17: F | C17: 4 | D17: C | E17: CMARTINEZ | F17: 17784 | G17: 46068 | H17: 46068.125 | I17: 46068.125 | J17: 46068.375 | K17: TRA-369 | L17: 01849 | M17: PONCE GALINDO, SANTOS | N17: WALMART PUEBLA | O17: CDCH-HUBP | P17: CHALCO DE DIAZ COVARRUBIAS, EDO. DE MEXICO | Q17: CUAUTLANCINGO, PUEBLA | R17: 604031-C | S17: 23294891 | T17: 97.5 | U17: 0 | V17: 1309655-1309656-1309642 | W17: 0 | X17: FWCH-0115716 | Y17: 2797.82 | Z17: 624.98 | AA17: 1143.53 | AB17: 1029.31 | AC17: 0 | AG17: 1 | AH17: 1 | AI17: 46077.449 | AJ17: ALEJANDRO MENDEZ | AK17: SANTOS PONCE GALINDO | AL17: 46068.719 | AM17: JUANMGC | AN17: 952YG3 | AO17: 144YC7 | AP17: =IF(ISNUMBER(FIND("C",R17)),"C","V") -> C
A18: NO ESTA EN POOL PÉRO ES DE F PUEBLA | B18: F | C18: 4 | D18: C | E18: CMARTINEZ | F18: 17795 | G18: 46068 | H18: 46068.125 | I18: 46068.125 | J18: 46068.375 | K18: TRA-321 | L18: 00622 | M18: CASOLCO ZARCO, CARLOS ALEJANDRO | N18: WALMART PUEBLA | O18: CDCH-HUBP | P18: CHALCO DE DIAZ COVARRUBIAS, EDO. DE MEXICO | Q18: CUAUTLANCINGO, PUEBLA | R18: 604037-C | S18: 23294556 | T18: 97.5 | U18: 0 | V18: 1309120-3318085-1309200-3318929 | W18: 0 | X18: FWCH-0115713 | Y18: 2797.82 | Z18: 624.98 | AA18: 1143.53 | AB18: 1029.31 | AC18: 0 | AD18: 141 | AG18: 1 | AH18: 1 | AI18: 46077.442 | AJ18: ALEJANDRO MENDEZ | AK18: CARLOS ALEJANDRO CASOLCO ZARCO | AL18: 46068.668 | AM18: JUANMGC | AN18: 32YA6C | AO18: 869YG5 | AP18: =IF(ISNUMBER(FIND("C",R18)),"C","V") -> C
A19: FULL CORDOBA | B19: F | C19: 4 | D19: C | E19: CMARTINEZ | F19: 17824 | G19: 46068 | H19: 46068.125 | I19: 46068.125 | J19: 46068.375 | K19: TOC-358 | L19: 01179 | M19: GARCIA PICHARDO, JESUS EUGENIO | N19: WALMART PUEBLA | O19: CDCH-HUBP | P19: CHALCO DE DIAZ COVARRUBIAS, EDO. DE MEXICO | Q19: CUAUTLANCINGO, PUEBLA | R19: 604930-C | S19: 23294977 | T19: 97.5 | U19: 0 | V19: 1309185-3318026-1309121 | W19: 0 | X19: FWCH-0115725 | Y19: 2797.82 | Z19: 624.98 | AA19: 1143.53 | AB19: 1029.31 | AC19: 0 | AG19: 1 | AH19: 1 | AI19: 46077.444 | AJ19: ALEJANDRO MENDEZ | AK19: JESUS EUGENIO GARCIA PICHARDO | AL19: 46068.868 | AM19: CARLOSPC | AN19: 760YF9 | AO19: 145YF5 | AP19: =IF(ISNUMBER(FIND("C",R19)),"C","V") -> C
A20: FULL CORDOBA | B20: F | C20: 4 | D20: C | E20: MROCIO | F20: 17967 | G20: 46068 | H20: 46068.125 | I20: 46068.125 | J20: 46068.375 | K20: TRA-255 | L20: 01875 | M20: SANTANA LEON, SERGIO | N20: WALMART PUEBLA | O20: CDCH-HUBP | P20: CHALCO DE DIAZ COVARRUBIAS, EDO. DE MEXICO | Q20: CUAUTLANCINGO, PUEBLA | R20: 604941-C | S20: 23296931 | T20: 97.5 | U20: 0 | V20: 1308889-3318846-1308971-3318883 | W20: 0 | X20: FWCH-0115741 | Y20: 2797.82 | Z20: 624.98 | AA20: 1143.53 | AB20: 1029.31 | AC20: 0 | AD20: 110 | AG20: 1 | AH20: 1 | AI20: 46076.723 | AJ20: ALEJANDRO MENDEZ | AK20: SERGIO SANTANA LEON | AL20: 46069.37 | AM20: ALBAAN | AN20: 60UH3B | AO20: 610YG8 | AP20: =IF(ISNUMBER(FIND("C",R20)),"C","V") -> C
A21: FULL CORDOBA | B21: F | C21: 4 | D21: C | E21: MROCIO | F21: 17969 | G21: 46068 | H21: 46068.125 | I21: 46068.125 | J21: 46068.375 | K21: TRA-252 | L21: 00796 | M21: VARGAS MARTINEZ, ERIK JULIO | N21: WALMART PUEBLA | O21: CDCH-HUBP | P21: CHALCO DE DIAZ COVARRUBIAS, EDO. DE MEXICO | Q21: CUAUTLANCINGO, PUEBLA | R21: 604944-C | S21: 23296920 | T21: 97.5 | U21: 0 | V21: 1308835-3318828-1308836 | W21: 0 | X21: FWCH-0115734 | Y21: 2797.82 | Z21: 624.98 | AA21: 1143.53 | AB21: 1029.31 | AC21: 0 | AD21: 111 | AG21: 1 | AH21: 1 | AI21: 46076.724 | AJ21: ALEJANDRO MENDEZ | AK21: ERIK JULIO VARGAS MARTINEZ | AL21: 46069.206 | AM21: CARLOSPC | AN21: 194YJ3 | AO21: 47UH1B | AP21: =IF(ISNUMBER(FIND("C",R21)),"C","V") -> C
A22: CUAUTI | B22: F | C22: 4 | D22: C | E22: MROCIO | F22: 17971 | G22: 46068 | H22: 46068.125 | I22: 46068.125 | J22: 46068.375 | K22: TOC-35 | L22: 00141 | M22: JIMENEZ DIAZ, VICTOR MANUEL | N22: WALMART PUEBLA | O22: CDCH-HUBP | P22: CHALCO DE DIAZ COVARRUBIAS, EDO. DE MEXICO | Q22: CUAUTLANCINGO, PUEBLA | R22: 604947-C | S22: 23296915 | T22: 97.5 | U22: 0 | V22: 1308882-3318829-1308975-3318886 | W22: 0 | X22: FWCH-0115731 | Y22: 2797.82 | Z22: 624.98 | AA22: 1143.53 | AB22: 1029.31 | AC22: 0 | AD22: 37 | AG22: 1 | AH22: 1 | AI22: 46077.406 | AJ22: ALEJANDRO MENDEZ | AK22: VICTOR MANUEL JIMENEZ DIAZ | AL22: 46069.069 | AM22: CARLOSPC | AN22: 675YF9 | AO22: 23YA4H | AP22: =IF(ISNUMBER(FIND("C",R22)),"C","V") -> C
A23: FULL CORDOBA | B23: F | C23: 4 | D23: C | E23: CMARTINEZ | F23: 18535 | G23: 46069 | H23: 46069 | I23: 46069 | J23: 46069 | K23: TRA-369 | L23: 01849 | M23: PONCE GALINDO, SANTOS | N23: WALMART PUEBLA | O23: HUBP-CDCH | P23: PUEBLA, PUEBLA | Q23: CHALCO DE DIAZ COVARRUBIAS, EDO. DE MEXICO | R23: 604832-V | S23: 23306693 | T23: 96.4 | U23: 0 | W23: 0 | X23: FWP-0241487 | Y23: 2770.07 | Z23: 617.92 | AA23: 1122.84 | AB23: 1029.31 | AC23: 0 | AD23: 61 | AG23: 1 | AH23: 1 | AI23: 46076.683 | AJ23: ALEJANDRO MENDEZ | AK23: SANTOS PONCE GALINDO | AL23: 46072.111 | AM23: JUANMGC | AP23: =IF(ISNUMBER(FIND("C",R23)),"C","V") -> V
A24: FULL CORDOBA | B24: F | C24: 4 | D24: C | E24: CMARTINEZ | F24: 18533 | G24: 46069 | H24: 46069.125 | I24: 46069.125 | J24: 46069.375 | K24: TRA-369 | L24: 01849 | M24: PONCE GALINDO, SANTOS | N24: WALMART PUEBLA | O24: CDCH-HUBP | P24: CHALCO DE DIAZ COVARRUBIAS, EDO. DE MEXICO | Q24: CUAUTLANCINGO, PUEBLA | R24: 604832-C | S24: 23302520 | T24: 97.5 | U24: 0 | V24: 1310557-3319838-1310453 | W24: 0 | X24: FWCH-0115760 | Y24: 2797.75 | Z24: 624.98 | AA24: 1143.46 | AB24: 1029.31 | AC24: 0 | AD24: 119 | AG24: 1 | AH24: 1 | AI24: 46076.772 | AJ24: ALEJANDRO MENDEZ | AK24: SANTOS PONCE GALINDO | AL24: 46069.789 | AM24: CARLOSPC | AN24: 718YG4 | AO24: 21UG9M | AP24: =IF(ISNUMBER(FIND("C",R24)),"C","V") -> C
A25: FULL CORDOBA | B25: F | C25: 4 | D25: C | E25: MROCIO | F25: 18773 | G25: 46070 | H25: 46070 | I25: 46070 | J25: 46070 | K25: TRA-330 | L25: 01649 | M25: MUÑOZ AMAYO, GABRIEL | N25: WALMART PUEBLA | O25: HUBP-CDCH | P25: PUEBLA, PUEBLA | Q25: CHALCO DE DIAZ COVARRUBIAS, EDO. DE MEXICO | R25: 604732-V | S25: 23342461 | T25: 96.4 | U25: 0 | W25: 0 | X25: FWP-0242039 | Y25: 2769.18 | Z25: 617.92 | AA25: 1121.95 | AB25: 1029.31 | AC25: 0 | AD25: 80 | AG25: 0 | AH25: 0 | AI25: 46076.447 | AJ25: . | AK25: . | AL25: 46076.646 | AM25: ELIZAPALE | AP25: =IF(ISNUMBER(FIND("C",R25)),"C","V") -> V
A26: NO ESTA EN POOL PÉRO ES DE F PUEBLA | B26: F | C26: 4 | D26: C | E26: MANUELJ | F26: 18873 | G26: 46070 | H26: 46070 | I26: 46070 | J26: 46070 | K26: TRA-321 | L26: 00622 | M26: CASOLCO ZARCO, CARLOS ALEJANDRO | N26: WALMART PUEBLA | O26: HUBP-CDCH | P26: PUEBLA, PUEBLA | Q26: CHALCO DE DIAZ COVARRUBIAS, EDO. DE MEXICO | R26: 604664-V | S26: 23338834 | T26: 96.4 | U26: 0 | W26: 0 | X26: FWP-0242031 | Y26: 2770.59 | Z26: 617.92 | AA26: 1123.36 | AB26: 1029.31 | AC26: 0 | AD26: 75 | AG26: 0 | AH26: 0 | AI26: 46076.468 | AJ26: . | AK26: . | AL26: 46076.643 | AM26: ELIZAPALE | AN26: XXXX | AO26: XXXX | AP26: =IF(ISNUMBER(FIND("C",R26)),"C","V") -> V
A27: FULL CORDOBA | B27: F | C27: 4 | D27: C | E27: MANUELJ | F27: 18927 | G27: 46070 | H27: 46070 | I27: 46070 | J27: 46070 | K27: TRA-324 | L27: 01384 | M27: SANCHEZ TEZOCO, ANTONIO | N27: WALMART PUEBLA | O27: HUBP-CDCH | P27: PUEBLA, PUEBLA | Q27: CHALCO DE DIAZ COVARRUBIAS, EDO. DE MEXICO | R27: 604674-V | S27: 23338861 | T27: 96.4 | U27: 0 | W27: 0 | X27: FWP-0242108 | Y27: 2772.4 | Z27: 618.57 | AA27: 1124.52 | AB27: 1029.31 | AC27: 0 | AD27: 85 | AG27: 0 | AH27: 0 | AI27: 46076.468 | AJ27: . | AK27: . | AL27: 46076.8 | AM27: ELIZAPALE | AN27: XXXX | AO27: XXXX | AP27: =IF(ISNUMBER(FIND("C",R27)),"C","V") -> V
A28: FULL CORDOBA | B28: F | C28: 4 | D28: C | E28: MROCIO | F28: 18772 | G28: 46070 | H28: 46070.125 | I28: 46070.125 | J28: 46070.375 | K28: TRA-330 | L28: 01649 | M28: MUÑOZ AMAYO, GABRIEL | N28: WALMART PUEBLA | O28: CDCH-HUBP | P28: CHALCO DE DIAZ COVARRUBIAS, EDO. DE MEXICO | Q28: CUAUTLANCINGO, PUEBLA | R28: 604732-C | S28: 23305126 | T28: 97.5 | U28: 0 | V28: 1311078-1311079-1311081 | W28: 0 | X28: FWCH-0115868 | Y28: 2797.8 | Z28: 624.98 | AA28: 1143.51 | AB28: 1029.31 | AC28: 0 | AD28: 124 | AG28: 1 | AH28: 1 | AI28: 46079.399 | AJ28: SILVIA | AK28: GABRIEL MUÑOZ AMAYO | AL28: 46070.334 | AM28: ALBAAN | AN28: 719YG5 | AO28: 78UJ6J | AP28: =IF(ISNUMBER(FIND("C",R28)),"C","V") -> C
A29: NO ESTA EN POOL PÉRO ES DE F PUEBLA | B29: F | C29: 4 | D29: C | E29: MANUELJ | F29: 18872 | G29: 46070 | H29: 46070.125 | I29: 46070.125 | J29: 46070.375 | K29: TRA-321 | L29: 00622 | M29: CASOLCO ZARCO, CARLOS ALEJANDRO | N29: WALMART PUEBLA | O29: CDCH-HUBP | P29: CHALCO DE DIAZ COVARRUBIAS, EDO. DE MEXICO | Q29: CUAUTLANCINGO, PUEBLA | R29: 604664-C | S29: 23306590 | T29: 97.5 | U29: 0 | V29: 1311606-3318939 / 1311790-3320736 | W29: 0 | X29: FWCH-0115880 | Y29: 2797.8 | Z29: 624.98 | AA29: 1143.51 | AB29: 1029.31 | AC29: 0 | AD29: 140 | AG29: 1 | AH29: 1 | AI29: 46079.422 | AJ29: SILVIA | AK29: CARLOS ALEJANDRO CASOLCO ZARCO | AL29: 46070.671 | AM29: CARLOSPC | AN29: 317YH5 | AO29: 339YG4 | AP29: =IF(ISNUMBER(FIND("C",R29)),"C","V") -> C
A30: FULL CORDOBA | B30: F | C30: 4 | D30: C | E30: MANUELJ | F30: 18926 | G30: 46070 | H30: 46070.125 | I30: 46070.125 | J30: 46070.375 | K30: TRA-324 | L30: 01384 | M30: SANCHEZ TEZOCO, ANTONIO | N30: WALMART PUEBLA | O30: CDCH-HUBP | P30: CHALCO DE DIAZ COVARRUBIAS, EDO. DE MEXICO | Q30: CUAUTLANCINGO, PUEBLA | R30: 604674-C | S30: 23307883 | T30: 97.5 | U30: 0 | V30: 1311118-1311119 / 1311101-1311102 | W30: 0 | X30: FWCH-0115879 | Y30: 2797.8 | Z30: 624.98 | AA30: 1143.51 | AB30: 1029.31 | AC30: 0 | AD30: 134 | AG30: 1 | AH30: 1 | AI30: 46079.423 | AJ30: SILVIA | AK30: ANTONIO SANCHEZ TEZOCO | AL30: 46070.661 | AM30: CARLOSPC | AN30: 78UH9R | AO30: 168YF9 | AP30: =IF(ISNUMBER(FIND("C",R30)),"C","V") -> C
A31: FULL CORDOBA | B31: F | C31: 4 | D31: C | E31: MANUELJ | F31: 19284 | G31: 46071 | H31: 46071 | I31: 46071 | J31: 46071 | K31: TOC-358 | L31: 01179 | M31: GARCIA PICHARDO, JESUS EUGENIO | N31: WALMART PUEBLA | O31: HUBP-CDCH | P31: PUEBLA, PUEBLA | Q31: CHALCO DE DIAZ COVARRUBIAS, EDO. DE MEXICO | R31: 604531-V | S31: 23321686 | T31: 96.4 | U31: 0 | W31: 0 | X31: FWP-0242170 | Y31: 2770.18 | Z31: 617.92 | AA31: 1122.95 | AB31: 1029.31 | AC31: 0 | AG31: 0 | AH31: 0 | AI31: 46077.449 | AJ31: . | AK31: . | AL31: 46077.674 | AM31: ELIZAPALE | AN31: XXXX | AO31: XXXX | AP31: =IF(ISNUMBER(FIND("C",R31)),"C","V") -> V
A32: CUAUTI | B32: F | C32: 4 | D32: C | E32: MANUELJ | F32: 19477 | G32: 46071 | H32: 46071 | I32: 46071 | J32: 46071 | K32: TOC-35 | L32: 00141 | M32: JIMENEZ DIAZ, VICTOR MANUEL | N32: WALMART PUEBLA | O32: CDCH-HUBP | P32: CHALCO DE DIAZ COVARRUBIAS, EDO. DE MEXICO | Q32: CUAUTLANCINGO, PUEBLA | R32: 606019-C | S32: 23318185 | T32: 97.5 | U32: 0 | V32: 311773-3320779 / 1311689-3320758 | W32: 0 | X32: FWCH-0116004 | Y32: 2797.63 | Z32: 624.98 | AA32: 1143.34 | AB32: 1029.31 | AC32: 0 | AD32: 52 | AG32: 1 | AH32: 1 | AI32: 46078.731 | AJ32: SILVIA | AK32: VICTOR MANUEL JIMENEZ DIAZ | AL32: 46071.941 | AM32: JUANMGC | AN32: 27YA4H | AO32: 08UH1S | AP32: =IF(ISNUMBER(FIND("C",R32)),"C","V") -> C
A33: CUAUTI | B33: F | C33: 3 | D33: A | E33: MANUELJ | F33: 19478 | G33: 46071 | H33: 46071 | I33: 46071 | J33: 46071 | K33: TOC-35 | L33: 00141 | M33: JIMENEZ DIAZ, VICTOR MANUEL | N33: WALMART PUEBLA | O33: HUBP-CDCH | P33: PUEBLA, PUEBLA | Q33: CHALCO DE DIAZ COVARRUBIAS, EDO. DE MEXICO | R33: 606019-V | S33: 23342527 | T33: 96.4 | U33: 0 | W33: 0 | X33: FWP-0242051 | Y33: 2769.18 | Z33: 617.92 | AA33: 1121.95 | AB33: 1029.31 | AC33: 0 | AG33: 0 | AH33: 0 | AI33: 46076.452 | AJ33: . | AK33: . | AL33: 46076.65 | AM33: ELIZAPALE | AN33: XXXX | AO33: XXXX | AP33: =IF(ISNUMBER(FIND("C",R33)),"C","V") -> V
A34: FULL CORDOBA | B34: F | C34: 4 | D34: C | E34: MANUELJ | F34: 19282 | G34: 46071 | H34: 46071.125 | I34: 46071.125 | J34: 46071.375 | K34: TOC-358 | L34: 01179 | M34: GARCIA PICHARDO, JESUS EUGENIO | N34: WALMART PUEBLA | O34: CDCH-HUBP | P34: CHALCO DE DIAZ COVARRUBIAS, EDO. DE MEXICO | Q34: CUAUTLANCINGO, PUEBLA | R34: 604531-C | S34: 23314495 | T34: 97.5 | U34: 0 | V34: 1312439-1312440 / 1312446-1312447 | W34: 0 | X34: FWCH-0115943 | Y34: 2797.63 | Z34: 624.98 | AA34: 1143.34 | AB34: 1029.31 | AC34: 0 | AG34: 0 | AH34: 0 | AL34: 46071.539 | AM34: ELIZAPALE | AN34: 864YG5 | AO34: 73YA9C | AP34: =IF(ISNUMBER(FIND("C",R34)),"C","V") -> C
A35: FULL CORDOBA | B35: F | C35: 3 | D35: A | E35: CMARTINEZ | F35: 19625 | G35: 46072 | H35: 46072 | I35: 46072 | J35: 46072 | K35: TRA-252 | L35: 00796 | M35: VARGAS MARTINEZ, ERIK JULIO | N35: WALMART PUEBLA | O35: HUBP-CDCH | P35: PUEBLA, PUEBLA | Q35: CHALCO DE DIAZ COVARRUBIAS, EDO. DE MEXICO | R35: 606066-V | S35: 23342548 | T35: 96.4 | U35: 0 | W35: 0 | X35: FWP-0242053 | Y35: 2769.18 | Z35: 617.92 | AA35: 1121.95 | AB35: 1029.31 | AC35: 0 | AD35: 79 | AG35: 0 | AH35: 0 | AI35: 46076.453 | AJ35: . | AK35: . | AL35: 46076.651 | AM35: ELIZAPALE | AP35: =IF(ISNUMBER(FIND("C",R35)),"C","V") -> V
A36: FULL CORDOBA | B36: F | C36: 2 | D36: A | E36: CMARTINEZ | F36: 19628 | G36: 46072 | I36: 46072 | K36: TRA-255 | L36: 01875 | M36: SANTANA LEON, SERGIO | N36: WALMART PUEBLA | O36: HUBP-CDCH | P36: PUEBLA, PUEBLA | Q36: CHALCO DE DIAZ COVARRUBIAS, EDO. DE MEXICO | R36: 606069-V | S36: 23331134 | T36: 96.4 | U36: 0 | W36: 0 | X36: FWP-0242193 | Y36: 2770.59 | Z36: 617.92 | AA36: 1123.36 | AB36: 1029.31 | AC36: 0 | AD36: 69 | AG36: 0 | AH36: 0 | AI36: 46077.458 | AJ36: . | AK36: . | AL36: 46077.708 | AM36: ELIZAPALE | AP36: =IF(ISNUMBER(FIND("C",R36)),"C","V") -> V
A37: CUAUTI | B37: F | C37: 3 | D37: A | E37: MROCIO | F37: 19784 | G37: 46072 | H37: 46072 | I37: 46072 | J37: 46072 | K37: TOC-35 | L37: 00141 | M37: JIMENEZ DIAZ, VICTOR MANUEL | N37: WALMART PUEBLA | O37: HUBP-CDCH | P37: PUEBLA, PUEBLA | Q37: CHALCO DE DIAZ COVARRUBIAS, EDO. DE MEXICO | R37: 606146-V | S37: 23338944 | T37: 96.4 | U37: 0 | W37: 0 | X37: FWP-0242032 | Y37: 2770.59 | Z37: 617.92 | AA37: 1123.36 | AB37: 1029.31 | AC37: 0 | AD37: 79 | AG37: 1 | AH37: 1 | AI37: 46077.469 | AJ37: ALEJANDRO MENDEZ | AK37: VICTOR MANUEL JIMENEZ DIAZ | AL37: 46076.644 | AM37: ELIZAPALE | AN37: XXXX | AO37: XXXX | AP37: =IF(ISNUMBER(FIND("C",R37)),"C","V") -> V
A38: FULL CORDOBA | B38: F | C38: 3 | D38: A | E38: MANUELJ | F38: 19918 | G38: 46072 | H38: 46072 | I38: 46072 | J38: 46072 | K38: TOC-358 | L38: 01179 | M38: GARCIA PICHARDO, JESUS EUGENIO | N38: WALMART PUEBLA | O38: HUBP-CDCH | P38: PUEBLA, PUEBLA | Q38: CHALCO DE DIAZ COVARRUBIAS, EDO. DE MEXICO | R38: 606143-V | S38: 23345326 | T38: 96.4 | U38: 0 | W38: 0 | X38: FWP-0242104 | Y38: 2769.18 | Z38: 617.92 | AA38: 1121.95 | AB38: 1029.31 | AC38: 0 | AD38: 70 | AG38: 1 | AH38: 1 | AI38: 46077.469 | AJ38: ALEJANDRO MENDEZ | AK38: JESUS EUGENIO GARCIA PICHARDO | AL38: 46076.798 | AM38: ELIZAPALE | AN38: XXXX | AO38: XXXX | AP38: =IF(ISNUMBER(FIND("C",R38)),"C","V") -> V
A39: FULL CORDOBA | B39: F | C39: 4 | D39: C | E39: CMARTINEZ | F39: 19624 | G39: 46072 | H39: 46072.125 | I39: 46072.125 | J39: 46072.375 | K39: TRA-252 | L39: 00796 | M39: VARGAS MARTINEZ, ERIK JULIO | N39: WALMART PUEBLA | O39: CDCH-HUBP | P39: CHALCO DE DIAZ COVARRUBIAS, EDO. DE MEXICO | Q39: CUAUTLANCINGO, PUEBLA | R39: 606066-C | S39: 23320673 | T39: 97.5 | U39: 0 | V39: 1311373-3321643-1313429-3321609 | W39: 0 | X39: FWCH-0116114 | Y39: 2797.52 | Z39: 624.98 | AA39: 1143.23 | AB39: 1029.31 | AC39: 0 | AD39: 108 | AG39: 0 | AH39: 0 | AL39: 46072.473 | AM39: ALBAAN | AN39: 49UF4S | AO39: 320YD2 | AP39: =IF(ISNUMBER(FIND("C",R39)),"C","V") -> C
A40: FULL CORDOBA | B40: F | C40: 4 | D40: C | E40: CMARTINEZ | F40: 19627 | G40: 46072 | H40: 46072.125 | I40: 46072.125 | J40: 46072.375 | K40: TRA-255 | L40: 01875 | M40: SANTANA LEON, SERGIO | N40: WALMART PUEBLA | O40: CDCH-HUBP | P40: CHALCO DE DIAZ COVARRUBIAS, EDO. DE MEXICO | Q40: CUAUTLANCINGO, PUEBLA | R40: 606069-C | S40: 23320654 | T40: 97.5 | U40: 0 | V40: 1312515-1312516-1312594-1312595 | W40: 0 | X40: FWCH-0116115 | Y40: 2797.52 | Z40: 624.98 | AA40: 1143.23 | AB40: 1029.31 | AC40: 0 | AD40: 130 | AG40: 0 | AH40: 0 | AL40: 46072.526 | AM40: ALBAAN | AN40: 341YH5 | AO40: 867YG5 | AP40: =IF(ISNUMBER(FIND("C",R40)),"C","V") -> C
...

Sheet RESUMEN 2
B2: UNIDADES SENCILLO EN VIAJES FULL | L2: RESOPE: | M2: ES EL PROGRAMA COMPARTIDO POR SISTEMAS PARA LLEVAR EL CONTROL DE LA ASISTENCIA DE LAS UNIDADES.
B3: UNIDAD | C3: VIAJES FULL CARGADOS | D3: COMENTARIOS
B4: TRA-321 | C4: =+COUNTIFS('S-FULL'!$K$3:$K$60,'RESUMEN 2'!B4,'S-FULL'!$AP$3:$AP$60,"C") -> 4 | D4: UNIDAD NO ES DEL CIRCUITO WALMART
B5: TRA-238 | C5: =+COUNTIFS('S-FULL'!$K$3:$K$60,'RESUMEN 2'!B5,'S-FULL'!$AP$3:$AP$60,"C") -> 3 | D5: TIENE ASISTENCIA EN RESOPE, PERO NO VIENE EN EL POOL PROPORCIONADO.
B6: TRA-255 | C6: =+COUNTIFS('S-FULL'!$K$3:$K$60,'RESUMEN 2'!B6,'S-FULL'!$AP$3:$AP$60,"C") -> 4 | D6: UNIDAD FULL CORDOBA
B7: TRA-330 | C7: =+COUNTIFS('S-FULL'!$K$3:$K$60,'RESUMEN 2'!B7,'S-FULL'!$AP$3:$AP$60,"C") -> 3 | D7: UNIDAD FULL CORDOBA
B8: TRA-369 | C8: =+COUNTIFS('S-FULL'!$K$3:$K$60,'RESUMEN 2'!B8,'S-FULL'!$AP$3:$AP$60,"C") -> 2 | D8: UNIDAD NO ES DEL CIRCUITO WALMART
B9: TOC-358 | C9: =+COUNTIFS('S-FULL'!$K$3:$K$60,'RESUMEN 2'!B9,'S-FULL'!$AP$3:$AP$60,"C") -> 4 | D9: UNIDAD FULL CORDOBA
B10: TRA-252 | C10: =+COUNTIFS('S-FULL'!$K$3:$K$60,'RESUMEN 2'!B10,'S-FULL'!$AP$3:$AP$60,"C") -> 2 | D10: UNIDAD NO ES DEL CIRCUITO WALMART
B11: TOC-35 | C11: =+COUNTIFS('S-FULL'!$K$3:$K$60,'RESUMEN 2'!B11,'S-FULL'!$AP$3:$AP$60,"C") -> 5 | D11: LA UNIDAD ORIGINALMENTE ESTABA EN CUAUTITLAN PERO PASO A SER SUSTITUIDA POR TRA-216/ DE IGUAL MANERA NO PERTENECE ESTA UNIDAD AL POOL DE PUEBLA
B12: TRA-324 | C12: =+COUNTIFS('S-FULL'!$K$3:$K$60,'RESUMEN 2'!B12,'S-FULL'!$AP$3:$AP$60,"C") -> 1 | D12: UNIDAD FULL CORDOBA
B13: ELM-280 | C13: =+COUNTIFS('S-FULL'!$K$3:$K$60,'RESUMEN 2'!B13,'S-FULL'!$AP$3:$AP$60,"C") -> 1 | D13: UNIDAD FULL CORDOBA
A14: TOTALES | B14: =+COUNTA(B4:B13) -> 10 | C14: =+SUM(C4:C13) -> 29
F21: FOTO COMPARTIDA DE POOL PUEBLA FULL
